[{"name": "test.test_powers_of_series.PowersOfSeries.test_called", "status": "passed", "message": "", "passed": true, "points": ["p04-02.1"], "backtrace": []}, {"name": "test.test_powers_of_series.PowersOfSeries.test_content", "status": "errored", "message": "1", "passed": false, "points": ["p04-02.1"], "backtrace": ["  File \"C:\\ProgramData\\Anaconda3\\lib\\unittest\\case.py\", line 59, in testPartExecutor\n    yield\n", "  File \"C:\\ProgramData\\Anaconda3\\lib\\unittest\\case.py\", line 615, in run\n    testMethod()\n", "  File \"C:\\Users\\koske\\Documents\\Koodit\\hy-data-analysis-with-python-summer-2019\\part04-e02_powers_of_series\\test\\test_powers_of_series.py\", line 46, in test_content\n    np.testing.assert_array_equal(df[i], s**i, err_msg=\"Incorrect values in column %i for Series\\n%s!\" % ( i, s))\n", "  File \"C:\\ProgramData\\Anaconda3\\lib\\site-packages\\pandas\\core\\frame.py\", line 2927, in __getitem__\n    indexer = self.columns.get_loc(key)\n", "  File \"C:\\ProgramData\\Anaconda3\\lib\\site-packages\\pandas\\core\\indexes\\base.py\", line 2659, in get_loc\n    return self._engine.get_loc(self._maybe_cast_indexer(key))\n", "  File \"pandas/_libs/index.pyx\", line 108, in pandas._libs.index.IndexEngine.get_loc\n", "  File \"pandas/_libs/index.pyx\", line 127, in pandas._libs.index.IndexEngine.get_loc\n", "  File \"pandas/_libs/index.pyx\", line 147, in pandas._libs.index.IndexEngine._get_loc_duplicates\n"]}, {"name": "test.test_powers_of_series.PowersOfSeries.test_dimensions", "status": "passed", "message": "", "passed": true, "points": ["p04-02.1"], "backtrace": []}, {"name": "test.test_powers_of_series.PowersOfSeries.test_type", "status": "passed", "message": "", "passed": true, "points": ["p04-02.1"], "backtrace": []}]