[{"name": "unittest.loader._FailedTest.test.test_solve_quadratic", "status": "errored", "message": "Failed to import test module: test.test_solve_quadratic\nTraceback (most recent call last):\n  File \"C:\\ProgramData\\Anaconda3\\lib\\unittest\\loader.py\", line 436, in _find_test_path\n    module = self._get_module_from_name(name)\n  File \"C:\\ProgramData\\Anaconda3\\lib\\unittest\\loader.py\", line 377, in _get_module_from_name\n    __import__(name)\n  File \"E:\\koodit\\hy-data-analysis-with-python-summer-2019\\part01-e08_solve_quadratic\\test\\test_solve_quadratic.py\", line 5, in <module>\n    import numpy as np\n  File \"C:\\ProgramData\\Anaconda3\\lib\\site-packages\\numpy\\__init__.py\", line 140, in <module>\n    from . import _distributor_init\n  File \"C:\\ProgramData\\Anaconda3\\lib\\site-packages\\numpy\\_distributor_init.py\", line 34, in <module>\n    from . import _mklinit\nImportError: DLL load failed: The specified module could not be found.\n", "passed": false, "points": [], "backtrace": ["  File \"C:\\ProgramData\\Anaconda3\\lib\\unittest\\case.py\", line 59, in testPartExecutor\n    yield\n", "  File \"C:\\ProgramData\\Anaconda3\\lib\\unittest\\case.py\", line 615, in run\n    testMethod()\n", "  File \"C:\\ProgramData\\Anaconda3\\lib\\unittest\\loader.py\", line 34, in testFailure\n    raise self._exception\n"]}]